<?xml version="1.0"?>
<!-- =================================================================================================== -->
<!-- |    This document was prepared by LarsVaehrens following the template from the kuka_allegro.urdf | -->
<!-- |    EDITING THIS FILE BY HAND IS NOT RECOMMENDED                                                 | -->
<!-- =================================================================================================== -->
<robot name="doosanh2017" xmlns:xacro="http://www.ros.org/wiki/xacro">
  <!-- materials -->
  <material name="black">
    <color rgba="0.0 0.0 0.0 1.0"/>
  </material>
  <material name="white">
    <color rgba="1.0 1.0 1.0 1.0"/>
  </material>
  <material name="orange">
    <color rgba="1.0 0.4 0.0 1.0"/>
  </material>
  <material name="dr_gray">
    <color rgba="0.490 0.490 0.486 1.0"/>
  </material>
  <material name="dr_white">
    <color rgba="0.941 0.941 0.941 1.0"/>
  </material>
  <!-- base_link -->
  <link name ="doosanh2017_base_link"/>
  <!--joint between base_link and link_0-->
  <joint name="doosanh2017_joint_0" type="fixed">
    <origin rpy="0 0 0" xyz="0 0 0 "/>
    <parent link="doosanh2017_base_link"/>
    <child link="doosanh2017_link_0"/>
  </joint>
  <!-- link_0 -->
  <link name="doosanh2017_link_0">
	<inertial>
      <mass value="3.722"/>
	  <origin xyz="-1.2e-05 -6e-05 0.050723"/>
	  <inertia ixx="0.011" ixy="-7.19e-06" ixz="-1.94e-06" iyy="0.011" iyz="4.9e-06" izz="0.014"/>
	</inertial>
	<visual>
	  <origin rpy="0 0 0" xyz="0 0 0"/>
	  <geometry>
		<mesh filename="doosanh2017/meshes/visual/H2017_0_0.obj" scale="0.001 0.001 0.001"/>
	  </geometry>
	</visual>
  </link>
  <!-- joint between link_0 and link_1 -->
  <joint name="doosanh2017_joint_1" type="revolute">
  	<parent link="doosanh2017_link_0"/>
  	<child link="doosanh2017_link_1"/>
  	<origin rpy="0 0 0" xyz="0 0 0.3443"/>
  	<axis xyz="0 0 1"/>
  	<limit effort="3460" lower="-6.283" upper="6.283" velocity="2.094"/>
  	<dynamics friction="0"/>
  </joint>
  <!-- link_1 -->
  <link name="doosanh2017_link_1">
  	<inertial>
  	  <mass value="7.446"/>
  	  <origin xyz="7e-05 0.044281 0.143327"/>
  	  <inertia ixx="0.039" ixy="2.1e-05" ixz="-3.61e-05" iyy="0.023" iyz="-0.003" izz="0.039"/>
  	</inertial>
    <collision>
      <geometry>
        <cylinder radius="0.1" length="0.2"/>
      </geometry>
    </collision>
  	<visual>
  	  <origin rpy="0 0 0" xyz="0 0 0"/>
  	  <geometry>
  	    <mesh filename="doosanh2017/meshes/visual/H2017_1_0.obj" scale="0.001 0.001 0.001"/>
  	  </geometry>
    </visual>
  </link>
  <!-- joint between link_1 and link_2 -->
  <joint name="doosanh2017_joint_2" type="revolute">
    <parent link="doosanh2017_link_1"/>
    <child link="doosanh2017_link_2"/>
    <origin rpy="0 -1.571 -1.571" xyz="0 0.0099 0"/>
    <axis xyz="0 0 1"/>
    <limit effort="3460" lower="-1.658" upper="1.658" velocity="2.094"/>
    <dynamics friction="0"/>
  </joint>
  <!-- link_2 -->
  <link name="doosanh2017_link_2">
  	 <inertial>
  	   <mass value="10.569"/>
  	   <origin xyz="-1.6e-05 0.189372 0.418558"/>
  	   <inertia ixx="0.820" ixy="1.19e-05" ixz="-0.000263" iyy="0.82" iyz="-0.008" izz="0.031"/>
  	 </inertial>
     <collision>
       <origin rpy="0 -1.571 0" xyz="0.3 0 0.1525"/>
       <geometry>
         <cylinder radius="0.08" length="0.75"/>
       </geometry>
     </collision>
  	 <visual>
  	   <origin rpy="0 0 0" xyz="0 0 0"/>
  	   <geometry>
  		 <mesh filename="doosanh2017/meshes/visual/H2017_2_0.obj" scale="0.001 0.001 0.001"/>
  	   </geometry>
  	 </visual>
  	 <visual>
  	   <origin rpy="0 0 0" xyz="0 0 0"/>
  	   <geometry>
  		 <mesh filename="doosanh2017/meshes/visual/H2017_2_1.obj" scale="0.001 0.001 0.001"/>
  	   </geometry>
  	 </visual>
  	 <visual>
  	   <origin rpy="0 0 0" xyz="0 0 0"/>
  	   <geometry>
  		 <mesh filename="doosanh2017/meshes/visual/H2017_2_2.obj" scale="0.001 0.001 0.001"/>
  	   </geometry>
  	 </visual>
  </link>
  <!-- joint between link_2 and link_3 -->
  <joint name="doosanh2017_joint_3" type="revolute">
  	 <parent link="doosanh2017_link_2"/>
  	 <child link="doosanh2017_link_3"/>
  	 <origin rpy="0 0 1.571" xyz="0.845 0 0"/>
  	 <axis xyz="0 0 1"/>
  	 <limit effort="1630" lower="-2.356" upper="2.356" velocity="3.142"/>
  	 <dynamics friction="0"/>
  </joint>
  <!-- link_3 -->
  <link name="doosanh2017_link_3">
  	 <inertial>
  	   <mass value="3.614"/>
  	   <origin xyz="6e-06 0.07917 0.781807"/>
  	   <inertia ixx="0.012" ixy="-4.38e-06" ixz="-1.2e-06" iyy="0.008" iyz="0.002" izz="0.011"/>
  	 </inertial>
     <visual>
  	   <origin rpy="0 0 0" xyz="0 0 0"/>
  	   <geometry>
  	     <mesh filename="doosanh2017/meshes/visual/H2017_3_0.obj" scale="0.001 0.001 0.001"/>
  	   </geometry>
  	 </visual>
  </link>
  <!-- joint between link_3 and link_4 -->
  <joint name="doosanh2017_joint_4" type="revolute">
  	 <parent link="doosanh2017_link_3"/>
  	 <child link="doosanh2017_link_4"/>
  	 <origin rpy="1.571 0 0" xyz="0 -0.734 0"/>
  	 <axis xyz="0 0 1"/>
  	 <limit effort="50" lower="-6.283" upper="6.283" velocity="3.927"/>
  	 <dynamics friction="0"/>
  </joint>
  <!-- link_4 -->
  <link name="doosanh2017_link_4">
    <inertial>
      <mass value="3.785"/>
      <origin xyz="-2.1e-05 0.12337 1.148"/>
      <inertia ixx="0.177" ixy="-2.34e-06" ixz="-4.92e-06" iyy="0.161" iyz="-0.05" izz="0.022"/>
    </inertial>
      <collision>
        <origin rpy="-0.55 0 0" xyz="0 0.07 -0.3"/>
        <geometry>
          <cylinder radius="0.07" length="0.4"/>
        </geometry>
      </collision>
    <visual>
      <origin rpy="0 0 0" xyz="0 0 0"/>
      <geometry>
    	<mesh filename="doosanh2017/meshes/visual/H2017_4_0.obj" scale="0.001 0.001 0.001"/>
      </geometry>
    </visual>
    <visual>
      <origin rpy="0 0 0" xyz="0 0 0"/>
      <geometry>
        <mesh filename="doosanh2017/meshes/visual/H2017_4_1.obj" scale="0.001 0.001 0.001"/>
      </geometry>
    </visual>
  </link>
  <!-- joint between link_4 and link_5 -->
  <joint name="doosanh2017_joint_5" type="revolute">
  	 <parent link="doosanh2017_link_4"/>
  	 <child link="doosanh2017_link_5"/>
  	 <origin rpy="-1.571 0 0" xyz="0 0 0"/>
  	 <axis xyz="0 0 1"/>
  	 <limit effort="50" lower="-2.356" upper="2.356" velocity="3.927"/>
  	 <dynamics friction="0"/>
  </joint>
  <!-- link_5 -->
  <link name="doosanh2017_link_5">
  	<inertial>
  	  <mass value="2.598"/>
  	  <origin xyz="-1.7e-05 0.06662 1.33103"/>
  	  <inertia ixx="0.007" ixy="-4.93e-06" ixz="-5.57e-06" iyy="0.004" iyz="-6.64e-05" izz="0.007"/>
  	</inertial>
      <collision>
        <origin rpy="1.571 0 0" xyz="0 0 0"/>
        <geometry>
          <cylinder radius="0.08" length="0.15"/>
        </geometry>
      </collision>
  	<visual>
  	  <origin rpy="0 0 0" xyz="0 0 0"/>
  	  <geometry>
  	    <mesh filename="doosanh2017/meshes/visual/H2017_5_0.obj" scale="0.001 0.001 0.001"/>
  	  </geometry>
  	</visual>
  </link>
  <!-- joint between link_5 and link_6 -->
  <joint name="doosanh2017_joint_6" type="revolute">
  	 <parent link="doosanh2017_link_5"/>
  	 <child link="doosanh2017_link_6"/>
  	 <origin rpy="1.571 0 0" xyz="0 -0.121 0"/>
  	 <axis xyz="0 0 1"/>
  	 <limit effort="50" lower="-6.283" upper="6.283" velocity="3.927"/>
  	 <dynamics friction="0"/>
  </joint>
  <!-- link_6 -->
  <link name="doosanh2017_link_6">
  	<inertial>
  	  <mass value="1.128"/>
  	  <origin xyz="-0.000174 0.034708 1.40022"/>
  	  <inertia ixx="0.001" ixy="-2.79e-06" ixz="5.78e-06" iyy="0.001" iyz="-6.67e-06" izz="0.001"/>
  	</inertial>
  	<visual>
  	  <origin rpy="0 0 0" xyz="0 0 0"/>
  	  <geometry>
  		<mesh filename="doosanh2017/meshes/visual/H2017_6_0.obj" scale="0.001 0.001 0.001"/>
  	  </geometry>
  	</visual>
  </link>
  <!-- joint between link_6 and link_ee -->
  <joint name="doosanh2017_joint_ee" type="fixed">
    <parent link="doosanh2017_link_6"/>
    <child link="doosanh2017_link_ee"/>
    <origin xyz="0 0 0.0" rpy="0 0 0"/>
  </joint>
  <!-- link_ee --> <!-- fake link -->
  <link name="doosanh2017_link_ee">
  </link>
  <!-- gazebo reference -->
  <gazebo reference="doosanh2017_link_0">
  	<kp>1000000.0</kp>
  	<kd>100.0</kd>
  	<mu1>30.0</mu1>
  	<mu2>30.0</mu2>
  	<maxVel>1.0</maxVel>
  	<minDepth>0.001</minDepth>
  </gazebo>
  <gazebo reference="doosanh2017_link_1">
  	<kp>1000000.0</kp>
  	<kd>100.0</kd>
  	<mu1>30.0</mu1>
  	<mu2>30.0</mu2>
  	<maxVel>1.0</maxVel>
  	<minDepth>0.001</minDepth>
  </gazebo>
  <gazebo reference="doosanh2017_link_2">
  	<kp>1000000.0</kp>
  	<kd>100.0</kd>
  	<mu1>30.0</mu1>
  	<mu2>30.0</mu2>
  	<maxVel>1.0</maxVel>
  	<minDepth>0.001</minDepth>
  </gazebo>
  <gazebo reference="doosanh2017_link_3">
  	<kp>1000000.0</kp>
  	<kd>100.0</kd>
  	<mu1>30.0</mu1>
  	<mu2>30.0</mu2>
  	<maxVel>1.0</maxVel>
  	<minDepth>0.001</minDepth>
  </gazebo>
  <gazebo reference="doosanh2017_link_4">
  	<kp>1000000.0</kp>
  	<kd>100.0</kd>
  	<mu1>30.0</mu1>
  	<mu2>30.0</mu2>
  	<maxVel>1.0</maxVel>
  	<minDepth>0.001</minDepth>
  </gazebo>
  <gazebo reference="doosanh2017_link_5">
    <kp>1000000.0</kp>
    <kd>100.0</kd>
    <mu1>30.0</mu1>
    <mu2>30.0</mu2>
    <maxVel>1.0</maxVel>
    <minDepth>0.001</minDepth>
  </gazebo>
  <gazebo reference="doosanh2017_link_6">
    <kp>1000000.0</kp>
    <kd>100.0</kd>
    <mu1>30.0</mu1>
    <mu2>30.0</mu2>
    <maxVel>1.0</maxVel>
    <minDepth>0.001</minDepth>
  </gazebo>
  <!-- transmission and motors -->
  <transmission name="doosanh2017_tran_1">
  	<type>transmission_interface/SimpleTransmission</type>
  	<joint name="doosanh2017_joint_1">
  	  <hardwareInterface>PositionJointInterface</hardwareInterface>
  	</joint>
  	<actuator name="doosanh2017_motor_1">
  	  <hardwareInterface>PositionJointInterface</hardwareInterface>
  	  <mechanicalReduction>1</mechanicalReduction>
  	</actuator>
  </transmission>
  <transmission name="doosanh2017_tran_2">
  	<type>transmission_interface/SimpleTransmission</type>
  	<joint name="doosanh2017_joint_2">
  	  <hardwareInterface>PositionJointInterface</hardwareInterface>
  	</joint>
  	<actuator name="doosanh2017_motor_2">
  	  <hardwareInterface>PositionJointInterface</hardwareInterface>
  	  <mechanicalReduction>1</mechanicalReduction>
  	</actuator>
  </transmission>
  <transmission name="doosanh2017_tran_3">
  	<type>transmission_interface/SimpleTransmission</type>
  	<joint name="doosanh2017_joint_3">
  	  <hardwareInterface>PositionJointInterface</hardwareInterface>
  	</joint>
  	<actuator name="doosanh2017_motor_3">
  	  <hardwareInterface>PositionJointInterface</hardwareInterface>
  	  <mechanicalReduction>1</mechanicalReduction>
  	</actuator>
  </transmission>
  <transmission name="doosanh2017_tran_4">
  	<type>transmission_interface/SimpleTransmission</type>
  	<joint name="doosanh2017_joint_4">
  	  <hardwareInterface>PositionJointInterface</hardwareInterface>
  	</joint>
  	<actuator name="doosanh2017_motor_4">
  	  <hardwareInterface>PositionJointInterface</hardwareInterface>
  	  <mechanicalReduction>1</mechanicalReduction>
  	</actuator>
  </transmission>
  <transmission name="doosanh2017_tran_5">
  	<type>transmission_interface/SimpleTransmission</type>
  	<joint name="doosanh2017_joint_5">
  	  <hardwareInterface>PositionJointInterface</hardwareInterface>
  	</joint>
  	<actuator name="doosanh2017_motor_5">
  	  <hardwareInterface>PositionJointInterface</hardwareInterface>
  	  <mechanicalReduction>1</mechanicalReduction>
  	</actuator>
  </transmission>
  <transmission name="doosanh2017_tran_6">
    <type>transmission_interface/SimpleTransmission</type>
  	<joint name="doosanh2017_joint_6">
  	  <hardwareInterface>PositionJointInterface</hardwareInterface>
  	</joint>
  	<actuator name="doosanh2017_motor_6">
  	  <hardwareInterface>PositionJointInterface</hardwareInterface>
  	  <mechanicalReduction>1</mechanicalReduction>
  	</actuator>
  </transmission>
</robot>
