<?xml version="1.0"?>
<!-- =================================================================================================== -->
<!-- |    This document was prepared by LarsVaehrens following the template from the kuka_allegro.urdf | -->
<!-- |    EDITING THIS FILE BY HAND IS NOT RECOMMENDED                                                 | -->
<!-- =================================================================================================== -->
<robot name="iiwa14" xmlns:xacro="http://www.ros.org/wiki/xacro">
  <!-- materials -->
  <material name="Black">
    <color rgba="0.0 0.0 0.0 1.0"/>
  </material>
  <material name="Blue">
    <color rgba="0.0 0.0 0.8 1.0"/>
  </material>
  <material name="Green">
    <color rgba="0.0 0.8 0.0 1.0"/>
  </material>
  <material name="Grey">
    <color rgba="0.4 0.4 0.4 1.0"/>
  </material>
  <material name="Orange">
    <color rgba="1.0 0.42352941176 0.03921568627 1.0"/>
  </material>
  <material name="Brown">
    <color rgba="0.87058823529 0.81176470588 0.76470588235 1.0"/>
  </material>
  <material name="Red">
    <color rgba="0.8 0.0 0.0 1.0"/>
  </material>
  <material name="White">
    <color rgba="1.0 1.0 1.0 1.0"/>
  </material>
  <!-- base_link -->
  <link name ="iiwa14_base_link"/>
  <!--joint between base_link and link_0-->
  <joint name="iiwa14_joint_0" type="fixed">
    <origin rpy="0 0 0" xyz="0 0 0 "/>
    <parent link="iiwa14_base_link"/>
    <child link="iiwa14_link_0"/>
  </joint>
  <!-- link_0 -->
  <link name="iiwa14_link_0">
    <inertial>
      <origin xyz="-0.1 0 0.07" rpy="0 0 0"/>
      <mass value="5"/>
      <inertia ixx="0.05" ixy="0" ixz="0" iyy="0.06" iyz="0" izz="0.03" />
    </inertial>
    <visual>
      <origin xyz="0 0 0" rpy="0 0 0"/>
      <geometry>
        <mesh filename="iiwa14/meshes/visual/link_0.obj"/>
      </geometry>
      <material name="Grey"/>
    </visual>
    <collision>
      <origin xyz="0 0 0" rpy="0 0 0"/>
      <geometry>
        <mesh filename="iiwa14/meshes/collision/link_0.obj"/>
      </geometry>
      <material name="Grey"/>
    </collision>
    <self_collision_checking>
      <origin xyz="0 0 0" rpy="0 0 0"/>
      <geometry>
        <capsule radius="0.15" length="0.25"/>
      </geometry>
    </self_collision_checking>
  </link>
  <!-- joint between link_0 and link_1 -->
  <joint name="iiwa14_joint_1" type="revolute">
    <parent link="iiwa14_link_0"/>
    <child link="iiwa14_link_1"/>
    <origin xyz="0 0 0.1575" rpy="0 0 0"/>
    <axis xyz="0 0 1"/>
    <limit lower="-2.96705972839" upper="2.96705972839" effort="300" velocity="10" />
    <safety_controller soft_lower_limit="-2.93215314335" soft_upper_limit="2.93215314335" k_position="100" k_velocity="2"/>
    <dynamics damping="0.5"/>
  </joint>
  <!-- link_1 -->
  <link name="iiwa14_link_1">
    <inertial>
      <origin xyz="0 -0.03 0.12" rpy="0 0 0"/>
      <mass value="4"/>
      <inertia ixx="0.1" ixy="0" ixz="0" iyy="0.09" iyz="0" izz="0.02" />
    </inertial>
    <visual>
      <origin xyz="0 0 0" rpy="0 0 0"/>
      <geometry>
        <mesh filename="iiwa14/meshes/visual/link_1.obj"/>
      </geometry>
      <material name="Orange"/>
    </visual>
    <collision>
      <origin xyz="0 0 0" rpy="0 0 0"/>
      <geometry>
        <mesh filename="iiwa14/meshes/collision/link_1.obj"/>
      </geometry>
      <material name="Orange"/>
    </collision>
  </link>
  <!-- joint between link_1 and link_2 -->
  <joint name="iiwa14_joint_2" type="revolute">
    <parent link="iiwa14_link_1"/>
    <child link="iiwa14_link_2"/>
    <origin xyz="0 0 0.2025" rpy="1.57079632679 0 3.1415926535897931"/>
    <axis xyz="0 0 1"/>
    <limit lower="-2.09439510239" upper="2.09439510239" effort="300" velocity="10" />
    <safety_controller soft_lower_limit="-2.05948851735" soft_upper_limit="2.05948851735" k_position="100" k_velocity="2"/>
    <dynamics damping="0.5"/>
  </joint>
  <!-- link_2 -->
  <link name="iiwa14_link_2">
    <inertial>
      <origin xyz="0.0003 0.059 0.042" rpy="0 0 0"/>
      <mass value="4"/>
      <inertia ixx="0.05"  ixy="0"  ixz="0" iyy="0.018" iyz="0" izz="0.044" />
    </inertial>
    <visual>
      <origin xyz="0 0 0" rpy="0 0 0"/>
      <geometry>
        <mesh filename="iiwa14/meshes/visual/link_2.obj"/>
      </geometry>
      <material name="Orange"/>
    </visual>
    <collision>
      <origin xyz="0 0 0" rpy="0 0 0"/>
      <geometry>
        <mesh filename="iiwa14/meshes/collision/link_2.obj"/>
      </geometry>
      <material name="Orange"/>
    </collision>
  </link>
  <!-- joint between link_2 and link_3 -->
  <joint name="iiwa14_joint_3" type="revolute">
    <parent link="iiwa14_link_2"/>
    <child link="iiwa14_link_3"/>
    <origin xyz="0 0.2045 0" rpy="1.57079632679 0 3.1415926535897931"/>
    <axis xyz="0 0 1"/>
    <limit lower="-2.96705972839" upper="2.96705972839" effort="300" velocity="10" />
    <safety_controller soft_lower_limit="-2.93215314335" soft_upper_limit="2.93215314335" k_position="100" k_velocity="2"/>
    <dynamics damping="0.5"/>
  </joint>
  <!-- link_3 -->
  <link name="iiwa14_link_3">
    <inertial>
      <origin xyz="0 0.03 0.13" rpy="0 0 0"/>
      <mass value="3"/>
      <inertia ixx="0.08" ixy="0" ixz="0" iyy="0.075" iyz="0" izz="0.01" />
    </inertial>
    <visual>
      <origin xyz="0 0 0" rpy="0 0 0"/>
      <geometry>
        <mesh filename="iiwa14/meshes/visual/link_3.obj"/>
      </geometry>
      <material name="Orange"/>
    </visual>
    <collision>
      <origin xyz="0 0 0" rpy="0 0 0"/>
      <geometry>
        <mesh filename="iiwa14/meshes/collision/link_3.obj"/>
      </geometry>
      <material name="Orange"/>
    </collision>
  </link>
  <!-- joint between link_3 and link_4 -->
  <joint name="iiwa14_joint_4" type="revolute">
    <parent link="iiwa14_link_3"/>
    <child link="iiwa14_link_4"/>
    <origin xyz="0 0 0.2155" rpy="1.57079632679 0 0"/>
    <axis xyz="0 0 1"/>
    <limit lower="-2.09439510239" upper="2.09439510239" effort="300" velocity="10" />
    <safety_controller soft_lower_limit="-2.05948851735" soft_upper_limit="2.05948851735" k_position="100" k_velocity="2"/>
    <dynamics damping="0.5"/>
  </joint>
  <!-- link_4 -->
  <link name="iiwa14_link_4">
    <inertial>
      <origin xyz="0 0.067 0.034" rpy="0 0 0"/>
      <mass value="2.7"/>
      <inertia ixx="0.03" ixy="0" ixz="0" iyy="0.01" iyz="0" izz="0.029" />
    </inertial>
    <visual>
      <origin xyz="0 0 0" rpy="0 0 0"/>
      <geometry>
        <mesh filename="iiwa14/meshes/visual/link_4.obj"/>
      </geometry>
      <material name="Orange"/>
    </visual>
    <collision>
      <origin xyz="0 0 0" rpy="0 0 0"/>
      <geometry>
        <mesh filename="iiwa14/meshes/collision/link_4.obj"/>
      </geometry>
      <material name="Orange"/>
    </collision>
  </link>
  <!-- joint between link_4 and link_5 -->
  <joint name="iiwa14_joint_5" type="revolute">
    <parent link="iiwa14_link_4"/>
    <child link="iiwa14_link_5"/>
    <origin xyz="0 0.1845 0" rpy="-1.57079632679 3.1415926535897931 0"/>
    <axis xyz="0 0 1"/>
    <limit lower="-2.96705972839" upper="2.96705972839" effort="300" velocity="10" />
    <safety_controller soft_lower_limit="-2.93215314335" soft_upper_limit="2.93215314335" k_position="100" k_velocity="2"/>
    <dynamics damping="0.5"/>
  </joint>
  <!-- link_5 -->
  <link name="iiwa14_link_5">
    <inertial>
      <origin xyz="0.0001 0.021 0.076" rpy="0 0 0"/>
      <mass value="1.7"/>
      <inertia ixx="0.02" ixy="0" ixz="0" iyy="0.018" iyz="0" izz="0.005" />
    </inertial>
    <visual>
      <origin xyz="0 0 0" rpy="0 0 0"/>
      <geometry>
        <mesh filename="iiwa14/meshes/visual/link_5.obj"/>
      </geometry>
      <material name="Orange"/>
    </visual>
    <collision>
      <origin xyz="0 0 0" rpy="0 0 0"/>
      <geometry>
        <mesh filename="iiwa14/meshes/collision/link_5.obj"/>
      </geometry>
      <material name="Orange"/>
    </collision>
  </link>
  <!-- joint between link_5 and link_6 -->
  <joint name="iiwa14_joint_6" type="revolute">
    <parent link="iiwa14_link_5"/>
    <child link="iiwa14_link_6"/>
    <origin xyz="0 0 0.2155" rpy="1.57079632679 0 0"/>
    <axis xyz="0 0 1"/>
    <limit lower="-2.09439510239" upper="2.09439510239" effort="300" velocity="10" />
    <safety_controller soft_lower_limit="-2.05948851735" soft_upper_limit="2.05948851735" k_position="100" k_velocity="2"/>
    <dynamics damping="0.5"/>
  </joint>
  <!-- link_6 -->
  <link name="iiwa14_link_6">
    <inertial>
      <origin xyz="0 0.0006 0.0004" rpy="0 0 0"/>
      <mass value="1.8"/>
      <inertia ixx="0.005" ixy="0" ixz="0" iyy="0.0036" iyz="0" izz="0.0047" />
    </inertial>
    <visual>
      <origin xyz="0 0 0" rpy="0 0 0"/>
      <geometry>
        <mesh filename="iiwa14/meshes/visual/link_6.obj"/>
      </geometry>
      <material name="Orange"/>
    </visual>
    <collision>
      <origin xyz="0 0 0" rpy="0 0 0"/>
      <geometry>
        <mesh filename="iiwa14/meshes/collision/link_6.obj"/>
      </geometry>
      <material name="Orange"/>
    </collision>
  </link>
  <!-- joint between link_6 and link_7 -->
  <joint name="iiwa14_joint_7" type="revolute">
    <parent link="iiwa14_link_6"/>
    <child link="iiwa14_link_7"/>
    <origin xyz="0 0.081 0" rpy="-1.57079632679 3.1415926535897931 0"/>
    <axis xyz="0 0 1"/>
    <limit lower="-3.05432619099" upper="3.05432619099" effort="300" velocity="10" />
    <safety_controller soft_lower_limit="-3.01941960595" soft_upper_limit="3.01941960595" k_position="100" k_velocity="2"/>
    <dynamics damping="0.5"/>
  </joint>
  <!-- link_7 -->
  <link name="iiwa14_link_7">
    <inertial>
      <origin xyz="0 0 0.02" rpy="0 0 0"/>
      <mass value="0.3"/>
      <inertia ixx="0.001" ixy="0" ixz="0" iyy="0.001" iyz="0" izz="0.001" />
    </inertial>
    <visual>
      <origin xyz="0 0 0" rpy="0 0 0"/>
      <geometry>
        <mesh filename="iiwa14/meshes/visual/link_7.obj"/>
      </geometry>
      <material name="Grey"/>
    </visual>
    <collision>
      <origin xyz="0 0 0" rpy="0 0 0"/>
      <geometry>
        <mesh filename="iiwa14/meshes/collision/link_7.obj"/>
      </geometry>
      <material name="Grey"/>
    </collision>
  </link>
  <!-- joint between link_7 and link_ee -->
  <joint name="iiwa14_joint_ee" type="fixed">
    <parent link="iiwa14_link_7"/>
    <child link="iiwa14_link_ee"/>
    <origin xyz="0 0 0.045" rpy="0 0 0"/>
  </joint>
  <!-- link_ee -->
  <link name="iiwa14_link_ee">
  </link>
  <!-- gazebo reference -->
  <gazebo reference="iiwa14_link_0">
    <material>Gazebo/Grey</material>
    <mu1>0.2</mu1>
    <mu2>0.2</mu2>
  </gazebo>
  <gazebo reference="iiwa14_link_1">
    <material>Gazebo/Orange</material>
    <mu1>0.2</mu1>
    <mu2>0.2</mu2>
  </gazebo>
  <gazebo reference="iiwa14_link_2">
    <material>Gazebo/Orange</material>
    <mu1>0.2</mu1>
    <mu2>0.2</mu2>
  </gazebo>
  <gazebo reference="iiwa14_link_3">
    <material>Gazebo/Orange</material>
    <mu1>0.2</mu1>
    <mu2>0.2</mu2>
  </gazebo>
  <gazebo reference="iiwa14_link_4">
    <material>Gazebo/Orange</material>
    <mu1>0.2</mu1>
    <mu2>0.2</mu2>
  </gazebo>
  <gazebo reference="iiwa14_link_5">
    <material>Gazebo/Orange</material>
    <mu1>0.2</mu1>
    <mu2>0.2</mu2>
  </gazebo>
  <gazebo reference="iiwa14_link_6">
    <material>Gazebo/Orange</material>
    <mu1>0.2</mu1>
    <mu2>0.2</mu2>
  </gazebo>
  <gazebo reference="iiwa14_link_7">
    <material>Gazebo/Grey</material>
    <mu1>0.2</mu1>
    <mu2>0.2</mu2>
  </gazebo>
  <!-- transmission and motors -->
  <transmission name="iiwa14_tran_1">
    <robotNamespace>/iiwa14</robotNamespace>
    <type>transmission_interface/SimpleTransmission</type>
    <joint name="iiwa14_joint_1">
      <hardwareInterface>PositionJointInterface</hardwareInterface>
    </joint>
    <actuator name="iiwa14_motor_1">
      <hardwareInterface>PositionJointInterface</hardwareInterface>
      <mechanicalReduction>1</mechanicalReduction>
    </actuator>
  </transmission>
  <transmission name="iiwa14_tran_2">
    <robotNamespace>/iiwa14</robotNamespace>
    <type>transmission_interface/SimpleTransmission</type>
    <joint name="iiwa14_joint_2">
      <hardwareInterface>PositionJointInterface</hardwareInterface>
    </joint>
    <actuator name="iiwa14_motor_2">
      <hardwareInterface>PositionJointInterface</hardwareInterface>
      <mechanicalReduction>1</mechanicalReduction>
    </actuator>
  </transmission>
  <transmission name="iiwa14_tran_3">
    <robotNamespace>/iiwa14</robotNamespace>
    <type>transmission_interface/SimpleTransmission</type>
    <joint name="iiwa14_joint_3">
      <hardwareInterface>PositionJointInterface</hardwareInterface>
    </joint>
    <actuator name="iiwa14_motor_3">
      <hardwareInterface>PositionJointInterface</hardwareInterface>
      <mechanicalReduction>1</mechanicalReduction>
    </actuator>
  </transmission>
  <transmission name="iiwa14_tran_4">
    <robotNamespace>/iiwa14</robotNamespace>
    <type>transmission_interface/SimpleTransmission</type>
    <joint name="iiwa14_joint_4">
      <hardwareInterface>PositionJointInterface</hardwareInterface>
    </joint>
    <actuator name="iiwa14_motor_4">
      <hardwareInterface>PositionJointInterface</hardwareInterface>
      <mechanicalReduction>1</mechanicalReduction>
    </actuator>
  </transmission>
  <transmission name="iiwa14_tran_5">
    <robotNamespace>/iiwa14</robotNamespace>
    <type>transmission_interface/SimpleTransmission</type>
    <joint name="iiwa14_joint_5">
      <hardwareInterface>PositionJointInterface</hardwareInterface>
    </joint>
    <actuator name="iiwa14_motor_5">
      <hardwareInterface>PositionJointInterface</hardwareInterface>
      <mechanicalReduction>1</mechanicalReduction>
    </actuator>
  </transmission>
  <transmission name="iiwa14_tran_6">
    <robotNamespace>/iiwa14</robotNamespace>
    <type>transmission_interface/SimpleTransmission</type>
    <joint name="iiwa14_joint_6">
      <hardwareInterface>PositionJointInterface</hardwareInterface>
    </joint>
    <actuator name="iiwa14_motor_6">
      <hardwareInterface>PositionJointInterface</hardwareInterface>
      <mechanicalReduction>1</mechanicalReduction>
    </actuator>
  </transmission>
  <transmission name="iiwa14_tran_7">
    <robotNamespace>/iiwa14</robotNamespace>
    <type>transmission_interface/SimpleTransmission</type>
    <joint name="iiwa14_joint_7">
      <hardwareInterface>PositionJointInterface</hardwareInterface>
    </joint>
    <actuator name="iiwa14_motor_7">
      <hardwareInterface>PositionJointInterface</hardwareInterface>
      <mechanicalReduction>1</mechanicalReduction>
    </actuator>
  </transmission>
</robot>
